<?xml version="1.0"?>


<robot name="kg2_gripper" xmlns:xacro="http://ros.org/wiki/xacro">
    <xacro:include filename="$(find movo_description)/urdf/manipulation/kinova_grippers/kg2_gripper.transmission.xacro" />
    <xacro:property name="M_PI" value="3.14159"/>
    
    
    <xacro:macro name="kg2_gripper" params="prefix parent *origin">

        <joint name="${prefix}gripper_base_joint" type="fixed">
            <parent link="${parent}"/>
            <child link="${prefix}gripper_base_link"/>
            <xacro:insert_block name="origin"/>
        </joint>
        
        <link name="${prefix}gripper_base_link">
        
            <visual>
                <geometry>
                    <mesh filename="package://movo_description/meshes/manipulation/kinova_grippers/visual/kg2_base_link.dae"/>
                </geometry>
            </visual>
            <collision>
                <geometry>
                    <mesh filename="package://movo_description/meshes/manipulation/kinova_grippers/collision/kg2_base_link.stl"/>
                </geometry>
            </collision>
            <inertial>
                <mass value="0.55" />
                <origin xyz="-0.00226 0.0 -0.068506" />
                <inertia ixx = "0.000609" ixy = "0.000000" ixz = "0.000004"
                         iyx = "0.000000" iyy = "0.000287" iyz = "0.000000"
                         izx = "0.000004" izy = "0.000000" izz = "0.000477" />
            </inertial>
        </link>
        
        <gazebo reference="${prefix}gripper_base_link">
        	<implicitSpringDamper>1</implicitSpringDamper>
            <kp>1000000.0</kp>
            <kd>1.0</kd>
            <mu1>0.8</mu1>
            <mu2>0.8</mu2>
            <maxVel>0.0</maxVel>
            <minDepth>0.0001</minDepth>
        </gazebo> 

        <joint name="${prefix}gripper_finger2_joint" type="revolute">
            <parent link="${prefix}gripper_base_link"/>
            <child link="${prefix}gripper_finger2_knuckle_link"/>
            <axis xyz="0 0 1"/>
            <origin rpy="${M_PI/2} 0 ${M_PI/2}" xyz="-0.0025 -0.0318523 -0.114816"/>
            <limit lower="0.0" upper="0.986111027" velocity="0.2" effort="3.0" damping="0.01" friction="0.005"/>
            <mimic joint="${prefix}gripper_finger1_joint"/>
        </joint>
        
        <link name="${prefix}gripper_finger2_knuckle_link">
            <visual>
                <geometry>
                    <mesh filename="package://movo_description/meshes/manipulation/kinova_grippers/visual/finger_knuckle.dae"/>
                </geometry>
            </visual>
            <collision>
                <geometry>
                    <mesh filename="package://movo_description/meshes/manipulation/kinova_grippers/collision/finger_knuckle.stl"/>
                </geometry>
            </collision>
            <inertial>
                <mass value="0.009127" />
                <origin xyz="-0.016752 -0.013874 0.0" />
                <inertia ixx = "0.000002" ixy = "0.000001" ixz = "0.000000"
                         iyx = "0.000001" iyy = "0.000001" iyz = "0.000000"
                         izx = "0.000000" izy = "0.000000" izz = "0.000002" />
            </inertial>
        </link>
        
        <gazebo reference="${prefix}gripper_finger2_knuckle_link">
        	<implicitSpringDamper>1</implicitSpringDamper>
            <kp>1000000.0</kp>
            <kd>1.0</kd>
            <mu1>0.8</mu1>
            <mu2>0.8</mu2>
            <maxVel>0.0</maxVel>
            <minDepth>0.0001</minDepth>
        </gazebo> 

        <joint name="${prefix}gripper_finger1_joint" type="revolute">
            <parent link="${prefix}gripper_base_link"/>
            <child link="${prefix}gripper_finger1_knuckle_link"/>
            <axis xyz="0 0 1"/>
            <origin rpy="${M_PI/2} 0 ${-M_PI/2}" xyz="-0.0025 0.0318523 -0.114816"/>
            <limit lower="0.0" upper="0.986111027" velocity="0.2" effort="3.0" damping="0.01" friction="0.005"/>
        </joint>
        
        <link name="${prefix}gripper_finger1_knuckle_link">
            <visual>
                <geometry>
                    <mesh filename="package://movo_description/meshes/manipulation/kinova_grippers/visual/finger_knuckle.dae"/>
                </geometry>
            </visual>
            <collision>
                <geometry>
                    <mesh filename="package://movo_description/meshes/manipulation/kinova_grippers/collision/finger_knuckle.stl"/>
                </geometry>
            </collision>
            <inertial>
                <mass value="0.009127" />
                <origin xyz="-0.016752 -0.013874 0.0" />
                <inertia ixx = "0.000002" ixy = "0.000001" ixz = "0.000000"
                         iyx = "0.000001" iyy = "0.000001" iyz = "0.000000"
                         izx = "0.000000" izy = "0.000000" izz = "0.000002" />
            </inertial>
        </link>
        
        <gazebo reference="${prefix}gripper_finger1_knuckle_link">
        	<implicitSpringDamper>1</implicitSpringDamper>
            <kp>1000000.0</kp>
            <kd>1.0</kd>
            <mu1>0.8</mu1>
            <mu2>0.8</mu2>
            <maxVel>0.0</maxVel>
            <minDepth>0.0001</minDepth>
        </gazebo> 

        <joint name="${prefix}gripper_finger2_finger_tip_joint" type="fixed">
            <parent link="${prefix}gripper_finger2_knuckle_link"/>
            <child link="${prefix}gripper_finger2_finger_tip_link"/>
            <origin xyz="-0.0245981 -0.036051 0.0" rpy="0 0 0" />
        </joint>

        <link name="${prefix}gripper_finger2_finger_tip_link">
            <visual>
                <geometry>
                    <mesh filename="package://movo_description/meshes/manipulation/kinova_grippers/visual/finger_tip.dae"/>
                </geometry>
            </visual>
            <collision>
                <geometry>
                    <mesh filename="package://movo_description/meshes/manipulation/kinova_grippers/collision/finger_tip.stl"/>
                </geometry>
            </collision>
            <inertial>
                <mass value="0.012690" />
                <origin xyz="-0.011926 -0.009701 0.0" />
                <inertia ixx = "0.000002" ixy = "0.000001" ixz = "0.000000"
                         iyx = "0.000001" iyy = "0.000001" iyz = "0.000000"
                         izx = "0.000000" izy = "0.000000" izz = "0.000002" />
            </inertial>
        </link>
        
        <gazebo reference="${prefix}gripper_finger2_finger_tip_link">
        	<implicitSpringDamper>1</implicitSpringDamper>
            <kp>1000000.0</kp>
            <kd>1.0</kd>
            <mu1>0.8</mu1>
            <mu2>0.8</mu2>
            <maxVel>0.0</maxVel>
            <minDepth>0.0001</minDepth>
        </gazebo> 
        
        <joint name="${prefix}gripper_finger1_finger_tip_joint" type="fixed">
            <parent link="${prefix}gripper_finger1_knuckle_link"/>
            <child link="${prefix}gripper_finger1_finger_tip_link"/>
            <origin xyz="-0.0245981 -0.036051 0.0" rpy="0 0 0" />
        </joint>
 

        <link name="${prefix}gripper_finger1_finger_tip_link">
            <visual>
                <geometry>
                    <mesh filename="package://movo_description/meshes/manipulation/kinova_grippers/visual/finger_tip.dae"/>
                </geometry>
            </visual>
            <collision>
                <geometry>
                    <mesh filename="package://movo_description/meshes/manipulation/kinova_grippers/collision/finger_tip.stl"/>
                </geometry>
            </collision>
            <inertial>
                <mass value="0.012690" />
                <origin xyz="-0.011926 -0.009701 0.0" />
                <inertia ixx = "0.000002" ixy = "0.000001" ixz = "0.000000"
                         iyx = "0.000001" iyy = "0.000001" iyz = "0.000000"
                         izx = "0.000000" izy = "0.000000" izz = "0.000002" />
            </inertial>
        </link>
        
        <gazebo reference="${prefix}gripper_finger1_finger_tip_link">
        	<implicitSpringDamper>1</implicitSpringDamper>
            <kp>1000000.0</kp>
            <kd>1.0</kd>
            <mu1>0.8</mu1>
            <mu2>0.8</mu2>
            <maxVel>0.0</maxVel>
            <minDepth>0.0001</minDepth>
        </gazebo>   
        
        <xacro:kg2_gripper_transmission prefix="${prefix}" />

    </xacro:macro>
</robot>
